Workbook

Sheet Sheet1
A1: loan_id | B1: customer_id | C1: principal | D1: annual_Interest_Rate | E1: processing_fees | F1: disbursement_date | G1: term_months | H1: repayment_frequency | I1: monthly_interest | J1: total_installment | K1: validation
A2: L001 | B2: C001 | C2: 50000 | D2: 0.48 | E2: 1000 | F2: 45840 | G2: 3 | H2: monthly | I2: =D2/12 -> 0.04 | J2: =C2*I2*G2+C2+E2 -> 57000 | K2: OK
A3: L002 | B3: C002 | C3: 70000 | D3: 0.48 | E3: 2000 | F3: 45872 | G3: 3 | H3: monthly | I3: =D3/12 -> 0.04 | J3: =C3*I3*G3+C3+E3 -> 80400 | K3: OK
A4: L003 | B4: C003 | C4: 90000 | D4: 0.48 | E4: 2000 | F4: 45842 | G4: 3 | H4: monthly | I4: =D4/12 -> 0.04 | J4: =C4*I4*G4+C4+E4 -> 102800 | K4: OK
A5: L004 | B5: C004 | C5: 110000 | D5: 0.48 | E5: 3000 | F5: 45907 | G5: 3 | H5: monthly | I5: =D5/12 -> 0.04 | J5: =C5*I5*G5+C5+E5 -> 126200 | K5: OK
A6: L005 | B6: C005 | C6: 130000 | D6: 0.48 | E6: 3000 | F6: 45938 | G6: 3 | H6: monthly | I6: =D6/12 -> 0.04 | J6: =C6*I6*G6+C6+E6 -> 148600 | K6: OK
A7: L006 | B7: C006 | C7: 150000 | D7: 0.48 | E7: 5000 | F7: 45847 | G7: 6 | H7: monthly | I7: =D7/12 -> 0.04 | J7: =C7*I7*G7+C7+E7 -> 191000 | K7: OK
A8: L007 | B8: C007 | C8: 170000 | D8: 0.48 | E8: 2500 | F8: 45848 | G8: 3 | H8: monthly | I8: =D8/12 -> 0.04 | J8: =C8*I8*G8+C8+E8 -> 192900 | K8: OK
A9: L008 | B9: C008 | C9: 60000 | D9: 0.48 | E9: 1000 | F9: 45849 | G9: 3 | H9: monthly | I9: =D9/12 -> 0.04 | J9: =C9*I9*G9+C9+E9 -> 68200 | K9: OK
A10: L009 | B10: C009 | C10: 80000 | D10: 0.48 | E10: 2000 | F10: 45850 | G10: 3 | H10: monthly | I10: =D10/12 -> 0.04 | J10: =C10*I10*G10+C10+E10 -> 91600 | K10: OK
A11: L010 | B11: C010 | C11: 100000 | D11: 0.48 | E11: 3000 | F11: 45851 | G11: 3 | H11: monthly | I11: =D11/12 -> 0.04 | J11: =C11*I11*G11+C11+E11 -> 115000 | K11: OK
A12: L011 | B12: C011 | C12: 120000 | D12: 0.48 | E12: 3000 | F12: 45852 | G12: 12 | H12: monthly | I12: =D12/12 -> 0.04 | J12: =C12*I12*G12+C12+E12 -> 180600 | K12: OK
A13: L012 | B13: C012 | C13: 140000 | D13: 0.48 | E13: 3000 | F13: 45853 | G13: 3 | H13: monthly | I13: =D13/12 -> 0.04 | J13: =C13*I13*G13+C13+E13 -> 159800 | K13: OK
... A21: L020 | B21: C020 | C21: 75000 | D21: 0.48 | E21: 1000 | F21: 45861 | G21: 3 | H21: monthly | I21: =D21/12 -> 0.04 | J21: =C21*I21*G21+C21+E21 -> 85000 | K21: OK

Sheet Flat Rate Balance
A1: loan_id | B1: inst_no | C1: due_date | D1: Opening Balance | E1: Principal | F1: Interest | G1: Fee | H1: Monthly payment | I1: total_installment | J1: Closing Balance
A2: L001 | B2: 1 | C2: 45871 | D2: =Sheet1!C2 -> 50000 | E2: =Sheet1!C2/Sheet1!G2 -> 16666.667 | F2: =Sheet1!C2*Sheet1!I2 -> 2000 | G2: =Sheet1!E2 -> 1000 | H2: =E2+F2 -> 18666.667 | I2: =E2+F2+G2 -> 19666.667 | J2: =D2-E2 -> 33333.333
A3: L001 | B3: 2 | C3: 45902 | D3: =J2 -> 33333.333 | E3: =E2 -> 16666.667 | F3: =F2 -> 2000 | G3: 0 | H3: =E3+F3 -> 18666.667 | I3: =E3+F3 -> 18666.667 | J3: =D3-E3 -> 16666.667
A4: L001 | B4: 3 | C4: 45932 | D4: =D3-E3 -> 16666.667 | E4: =E2 -> 16666.667 | F4: =F2 -> 2000 | G4: 0 | H4: =E4+F4 -> 18666.667 | I4: =E4+F4 -> 18666.667 | J4: =D4-E4 -> 0
A5: L002 | B5: 1 | C5: 45903 | D5: =Sheet1!C3 -> 70000 | E5: =Sheet1!C3/Sheet1!G3 -> 23333.333 | F5: =Sheet1!C3*Sheet1!I3 -> 2800 | G5: =Sheet1!E3 -> 2000 | H5: =E5+F5 -> 26133.333 | I5: =E5+F5+G5 -> 28133.333 | J5: =D5-E5 -> 46666.667
A6: L002 | B6: 2 | C6: 45933 | D6: =J5 -> 46666.667 | E6: =E5 -> 23333.333 | F6: =F5 -> 2800 | G6: 0 | H6: =E6+F6 -> 26133.333 | I6: =H6+F6 -> 28933.333 | J6: =D6-E6 -> 23333.333
A7: L002 | B7: 3 | C7: 45964 | D7: =J5-E7 -> 23333.333 | E7: =E6 -> 23333.333 | F7: =F6 -> 2800 | G7: 0 | H7: =E7+F7 -> 26133.333 | I7: =H7+F7 -> 28933.333 | J7: =D7-E7 -> 0
A8: L003 | B8: 1 | C8: 45873 | D8: =Sheet1!C4 -> 90000 | E8: =Sheet1!C4/Sheet1!G4 -> 30000 | F8: =Sheet1!C4*Sheet1!I4 -> 3600 | G8: =Sheet1!E4 -> 2000 | H8: =E8+F8 -> 33600 | I8: =E8+F8+G8 -> 35600 | J8: =D8-E8 -> 60000
A9: L003 | B9: 2 | C9: 45904 | D9: =J8 -> 60000 | E9: =E8 -> 30000 | F9: =F8 -> 3600 | G9: 0 | H9: =E9+F9 -> 33600 | I9: =E9+F9 -> 33600 | J9: =J8-E9 -> 30000
A10: L003 | B10: 3 | C10: 45934 | D10: =J9 -> 30000 | E10: =E9 -> 30000 | F10: =F9 -> 3600 | G10: 0 | H10: =E10+F10 -> 33600 | I10: =E10+F10 -> 33600 | J10: =J9-E10 -> 0
A11: L004 | B11: 1 | C11: 45937 | D11: =Sheet1!C5 -> 110000 | E11: =Sheet1!C5/Sheet1!G4 -> 36666.667 | F11: 4400 | G11: =Sheet1!E5 -> 3000 | H11: =E11+F11 -> 41066.667 | I11: =E11+F11+G11 -> 44066.667 | J11: =D11-E11 -> 73333.333
A12: L004 | B12: 2 | C12: 45968 | D12: =J11 -> 73333.333 | E12: =E11 -> 36666.667 | F12: 4400 | G12: 0 | H12: =E12+F12 -> 41066.667 | I12: =E12+F12 -> 41066.667 | J12: =D12-E12 -> 36666.667
A13: L004 | B13: 3 | C13: 45998 | D13: =J11-E12 -> 36666.667 | E13: =E12 -> 36666.667 | F13: 4400 | G13: 0 | H13: =E13+F12 -> 41066.667 | I13: =E13+F13 -> 41066.667 | J13: =D13-E13 -> 0
A14: L005 | B14: 1 | C14: 45969 | D14: =Sheet1!C6 -> 130000 | E14: =Sheet1!C6/Sheet1!G5 -> 43333.333 | F14: =Sheet1!C6*Sheet1!I6 -> 5200 | G14: =Sheet1!E6 -> 3000 | H14: =E14+F14 -> 48533.333 | I14: =E14+F14+G14 -> 51533.333 | J14: =D14-E14 -> 86666.667
A15: L005 | B15: 2 | C15: 45999 | D15: =J14 -> 86666.667 | E15: =E14 -> 43333.333 | F15: =F14 -> 5200 | G15: 0 | H15: =E15+F15 -> 48533.333 | I15: =E15+F15 -> 48533.333 | J15: =D15-E15 -> 43333.333
A16: L005 | B16: 3 | C16: 46030 | D16: =J15 -> 43333.333 | E16: =E15 -> 43333.333 | F16: =F15 -> 5200 | G16: 0 | H16: =E16+F16 -> 48533.333 | I16: =E16+F16 -> 48533.333 | J16: =D16-E16 -> 0
A17: L006 | B17: 1 | C17: 45878 | D17: =Sheet1!C7 -> 150000 | E17: =Sheet1!C7/Sheet1!G7 -> 25000 | F17: =Sheet1!C7*Sheet1!I7 -> 6000 | G17: =Sheet1!E7 -> 5000 | H17: =D17/Sheet1!G7 -> 25000 | I17: =E17+G17+F17 -> 36000 | J17: =D17-E17 -> 125000
A18: L006 | B18: 2 | C18: 45909 | D18: =J17 -> 125000 | E18: =E17 -> 25000 | F18: =F17 -> 6000 | G18: 0 | H18: =H17 -> 25000 | I18: =E18+F18 -> 31000 | J18: =D18-H18 -> 100000
A19: L006 | B19: 3 | C19: 45939 | D19: =D18-H18 -> 100000 | E19: =E18 -> 25000 | F19: =F18 -> 6000 | G19: 0 | H19: =H18 -> 25000 | I19: =E19+F19 -> 31000 | J19: =D19-H19 -> 75000
A20: L006 | B20: 4 | C20: 45970 | D20: =D19-H19 -> 75000 | E20: =E19 -> 25000 | F20: =F19 -> 6000 | G20: 0 | H20: =H19 -> 25000 | I20: =E20+F20 -> 31000 | J20: =D20-H20 -> 50000 | K20: =SUM(I17:I22) -> 191000
A21: L006 | B21: 5 | C21: 46000 | D21: =D20-H20 -> 50000 | E21: =E20 -> 25000 | F21: =F20 -> 6000 | G21: 0 | H21: =H20 -> 25000 | I21: =E21+F21 -> 31000 | J21: =D21-H21 -> 25000
A22: L006 | B22: 6 | C22: 46031 | D22: =D21-H21 -> 25000 | E22: =E21 -> 25000 | F22: =F21 -> 6000 | G22: 0 | H22: =H21 -> 25000 | I22: =E22+F22 -> 31000 | J22: =D22-H22 -> 0
A23: L007 | B23: 1 | C23: 45879 | D23: =Sheet1!C8 -> 170000 | E23: =Sheet1!C8/Sheet1!G8 -> 56666.667 | F23: =Sheet1!C8*Sheet1!I8 -> 6800 | G23: =Sheet1!E8 -> 2500 | H23: =Sheet1!C8/Sheet1!G8 -> 56666.667 | I23: =H23+F23+G23 -> 65966.667 | J23: =D23-H23 -> 113333.33
A24: L007 | B24: 2 | C24: 45910 | D24: =J23 -> 113333.33 | E24: =E23 -> 56666.667 | F24: =F23 -> 6800 | G24: 0 | H24: =H23 -> 56666.667 | I24: =E24+F24 -> 63466.667 | J24: =D24-H24 -> 56666.667
A25: L007 | B25: 3 | C25: 45940 | D25: =J24 -> 56666.667 | E25: =E24 -> 56666.667 | F25: =F24 -> 6800 | G25: 0 | H25: =H24 -> 56666.667 | I25: =E25+F25 -> 63466.667 | J25: =D25-H25 -> 0
A26: L008 | B26: 1 | C26: 45880 | D26: =Sheet1!C9 -> 60000 | E26: =Sheet1!C9/Sheet1!G9 -> 20000 | F26: =Sheet1!C9*Sheet1!I9 -> 2400 | G26: =Sheet1!E9 -> 1000 | H26: =E26+F26 -> 22400 | I26: =F26+E26+G26 -> 23400 | J26: =D26-H26 -> 37600
A27: L008 | B27: 2 | C27: 45911 | D27: =J26 -> 37600 | E27: =E26 -> 20000 | F27: 2400 | G27: 0 | H27: =H26 -> 22400 | I27: =E27+F27 -> 22400 | J27: =D27-H27 -> 15200
A28: L008 | B28: 3 | C28: 45941 | D28: =J27 -> 15200 | E28: =E27 -> 20000 | F28: 2400 | G28: 0 | H28: =H27 -> 22400 | I28: =E28+F28 -> 22400 | J28: =D28-H28 -> -7200
A29: L009 | B29: 1 | C29: 45881 | D29: =Sheet1!C10 -> 80000 | E29: =Sheet1!C10/Sheet1!G10 -> 26666.667 | F29: =Sheet1!C10*Sheet1!I10 -> 3200 | G29: =Sheet1!E9 -> 1000 | H29: =E29+F29 -> 29866.667 | I29: =E29+F29+G29 -> 30866.667 | J29: =D29-H29 -> 50133.333
A30: L009 | B30: 2 | C30: 45912 | D30: =J29 -> 50133.333 | E30: =E29 -> 26666.667 | F30: =F29 -> 3200 | G30: 0 | H30: =H29 -> 29866.667 | I30: =E30+F30 -> 29866.667 | J30: =D30-H30 -> 20266.667
A31: L009 | B31: 3 | C31: 45942 | D31: =D30-E30 -> 23466.667 | E31: =E30 -> 26666.667 | F31: =F30 -> 3200 | G31: 0 | H31: =H30 -> 29866.667 | I31: =E31+F31 -> 29866.667 | J31: =D31-H31 -> -6400
A32: L010 | B32: 1 | C32: 45882 | D32: =Sheet1!C11 -> 100000 | E32: =Sheet1!C11/Sheet1!G11 -> 33333.333 | F32: =Sheet1!C11*Sheet1!I11 -> 4000 | G32: =Sheet1!E11 -> 3000 | H32: =E32+F32 -> 37333.333 | I32: =E32+F32+G32 -> 40333.333 | J32: =D32-H32 -> 62666.667
A33: L010 | B33: 2 | C33: 45913 | D33: =J32 -> 62666.667 | E33: =E32 -> 33333.333 | F33: =F32 -> 4000 | G33: 0 | H33: =H32 -> 37333.333 | I33: =I32-G32 -> 37333.333 | J33: =D33-H33 -> 25333.333
A34: L010 | B34: 3 | C34: 45943 | D34: =J33 -> 25333.333 | E34: =E33 -> 33333.333 | F34: =F33 -> 4000 | G34: 0 | H34: =H33 -> 37333.333 | I34: =I33 -> 37333.333 | J34: =D34-H34 -> -12000
A35: L011 | B35: 1 | C35: 45883
A36: L011 | B36: 2 | C36: 45914
A37: LO11 | B37: 3 | C37: 45944
A38: L012 | B38: 1 | C38: 45884
A39: L012 | B39: 2 | C39: 45915
A40: L012 | B40: 3 | C40: 45945
...

Sheet Reducing Balance Schedule
A1: Payment No | B1: Due Date | C1: Opening Balance | D1: Principal | E1: Interest | F1: Fee | G1: Monthly payment | H1: Closing Balance

Sheet Scenario Comparison
A1: Scenario | B1: Principal (₦) | C1: months | D1: Monthly Rate | E1: Fee | F1: Flat: Total Repayment (₦) | G1: Reducing: Total Repayment (₦) | H1: Savings with Reducing (₦)
A2: Scenario 1 | B2: 50000 | C2: 3 | D2: 0.04 | E2: 1000 | F2: =B2+(B2*D2*C2)+E2 -> 57000 | G2: =(-PMT(D2,C2,B2))*C2+E2 -> 55052.281 | H2: =F2-G2 -> 1947.7191
A3: Scenario 2 | B3: 150000 | C3: 6 | D3: 0.04 | E3: 5000 | F3: =B3+(B3*D3*C3)+E3 -> 191000 | G3: =(-PMT(D3,C3,B3))*C3+E3 -> 176685.71 | H3: =F3-G3 -> 14314.288
A4: Scenario 3 | B4: 500000 | C4: 12 | D4: 0.04 | E4: 12500 | F4: =B4+(B4*D4*C4)+E4 -> 752500 | G4: =(-PMT(D4,C4,B4))*C4+E4 -> 651813.04 | H4: =F4-G4 -> 100686.96
