Workbook

Sheet Customer
A1: customer_id | B1: customer_names | C1: state | D1: age | E1: employment_type | F1: monthly_income | G1: income_consistency | H1: account_age_months | J1: signup_date | K1: signup_date
A2: C001 | B2: Solomon Yakubu | C2: Lagos | D2: 32 | E2: Employee | F2: 250000 | G2: High | H2: 18 | I2: 45660
A3: C002 | B3: Aminat Abdul | C3: Abuja | D3: 27 | E3: Self-employed | F3: 180000 | G3: Medium | H3: 17 | I3: 45660
A4: C003 | B4: Jabari Woji | C4: Rivers | D4: 41 | E4: Business Owner | F4: 520000 | G4: High | H4: 16 | I4: 45690
A5: C004 | B5: Usman Hazeem | C5: Kano | D5: 36 | E5: Salaried | F5: 320000 | G5: High | H5: 15 | I5: 46054
A6: C005 | B6: Ademola Adeola | C6: Oyo | D6: 29 | E6: Freelancer | F6: 150000 | G6: Low | H6: 14 | I6: 45728
A7: C006 | B7: Onyekachi Anyanwu | C7: Enugu | D7: 38 | E7: Business Owner | F7: 470000 | G7: Medium | H7: 13 | I7: 45759
A8: C007 | B8: Olivia Idu | C8: Delta | D8: 24 | E8: Employee | F8: 170000 | G8: High | H8: 12 | I8: 45787
A9: C008 | B9: Amarachi Oke | C9: Kaduna | D9: 45 | E9: Contractor | F9: 600000 | G9: Medium | H9: 11 | I9: 45785
A10: C009 | B10: Oyin Lekan | C10: Ogun | D10: 30 | E10: Self-employed | F10: 210000 | G10: Medium | H10: 10 | I10: 45813
A11: C010 | B11: Ambrose Okafor | C11: Anambra | D11: 34 | E11: Employee | F11: 390000 | G11: High | H11: 9 | I11: 45817
A12: C011 | B12: Grace Nwaji | C12: Abia | D12: 32 | E12: Employee | F12: 250000 | G12: High | H12: 18 | I12: 46025
A13: C012 | B13: Nsikak Effiong | C13: Uyo | D13: 27 | E13: Self-employed | F13: 180000 | G13: Medium | H13: 17 | I13: 46025
... A21: C020 | B21: Clement Orji | C21: Anambra | D21: 34 | E21: Employee | F21: 390000 | G21: High | H21: 9 | I21: 45756

Sheet Application
A1: application_id | B1: customer_id | C1: application_date | D1: product | E1: requested_amount | F1: term_months | G1: bureau_score | H1: existing_debt_payment | I1: proposed_instalment | J1: decision | K1: accepted_flag
A2: A001 | B2: C001 | C2: 45810 | D2: Personal Loan | E2: 300000 | F2: 3 | G2: 725 | H2: 20000 | I2: 29500 | J2: Approved | K2: 1
A3: A002 | B3: C002 | C3: 45811 | D3: Salary Advance | E3: 100000 | F3: 3 | G3: 650 | H3: 15000 | I3: 18500 | J3: Approved | K3: 1
A4: A003 | B4: C003 | C4: 45812 | D4: Personal Loan | E4: 500000 | F4: 3 | G4: 780 | H4: 30000 | I4: 37000 | J4: Approved | K4: 1
A5: A004 | B5: C004 | C5: 45813 | D5: Business Loan | E5: 600000 | F5: 3 | G5: 590 | H5: 45000 | I5: 43000 | J5: Approved | K5: 0
A6: A005 | B6: C005 | C6: 45814 | D6: Salary Advance | E6: 80000 | F6: 3 | G6: 520 | H6: 22000 | I6: 28500 | J6: Approved | K6: 0
A7: A006 | B7: C006 | C7: 45815 | D7: Business Loan | E7: 700000 | F7: 3 | G7: 735 | H7: 35000 | I7: 47000 | J7: Approved | K7: 1
A8: A007 | B8: C007 | C8: 45816 | D8: Personal Loan | E8: 200000 | F8: 3 | G8: 680 | H8: 12000 | I8: 21000 | J8: Approved | K8: 1
A9: A008 | B9: C008 | C9: 45817 | D9: Business Loan | E9: 1000000 | F9: 3 | G9: 760 | H9: 60000 | I9: 52000 | J9: Rejected | K9: 1
A10: A009 | B10: C009 | C10: 45818 | D10: Salary Advance | E10: 120000 | F10: 3 | G10: 605 | H10: 18000 | I10: 21000 | J10: Approved | K10: 1
A11: A010 | B11: C010 | C11: 45819 | D11: Personal Loan | E11: 350000 | F11: 3 | G11: 745 | H11: 20000 | I11: 33000 | J11: Approved | K11: 1
A12: A011 | B12: C011 | C12: 45820 | D12: Salary Advance | E12: 120000 | F12: 3 | G12: 730 | H12: 15000 | I12: 22000 | J12: Approved | K12: 1
A13: A012 | B13: C012 | C13: 45821 | D13: Business Loan | E13: 900000 | F13: 3 | G13: 790 | H13: 40000 | I13: 61000 | J13: Rejected | K13: 1
... A21: A020 | B21: C020 | C21: 45829 | D21: Personal Loan | E21: 450000 | F21: 3 | G21: 768 | H21: 3000 | I21: 120000 | J21: Approved | K21: 1

Sheet Loan
A1: loan_id | B1: application_id | C1: customer_id | D1: disbursement_date | E1: principal | F1: monthly_ interest_rate | G1: processing_fees | H1: term_months | I1: maturity_date | J1: total_amount
A2: L001 | B2: A001 | C2: C001 | D2: 45840 | E2: 50000 | F2: =48%/12 -> 0.04 | G2: 1000 | H2: 3 | I2: 46297 | J2: =E2*F2*3+E2+G2 -> 57000
A3: L002 | B3: A002 | C3: C002 | D3: 45872 | E3: 70000 | F3: =48%/12 -> 0.04 | G3: 3000 | H3: 3 | I3: 46330 | J3: =E3*F3*3+G3+E3 -> 81400
A4: L003 | B4: A003 | C4: C003 | D4: 45842 | E4: 90000 | F4: =48%/12 -> 0.04 | G4: 2000 | H4: 3 | I4: 46300 | J4: =E2*F2*3+G4+E4 -> 98000
A5: L004 | B5: A004 | C5: C004 | D5: 45907 | E5: 110000 | F5: =48%/12 -> 0.04 | G5: 3000 | H5: 3 | I5: 46301 | J5: =E5*F5*H5+G5+E5 -> 126200
A6: L005 | B6: A005 | C6: C005 | D6: 45938 | E6: 130000 | F6: =48%/12 -> 0.04 | G6: 3000 | H6: 3 | I6: 46302 | J6: =E6*F6*H6+G6+E6 -> 148600
A7: L006 | B7: A006 | C7: C006 | D7: 45847 | E7: 150000 | F7: =48%/12 -> 0.04 | G7: 5000 | H7: 3 | I7: 46303 | J7: =E7*F7*H7+G7+E7 -> 173000
A8: L007 | B8: A007 | C8: C007 | D8: 45848 | E8: 170000 | F8: =48%/12 -> 0.04 | G8: 2500 | H8: 3 | I8: 46304 | J8: =E8*F8*H8+G8+E8 -> 192900
A9: L008 | B9: A008 | C9: C008 | D9: 45849 | E9: 60000 | F9: =48%/12 -> 0.04 | G9: 1000 | H9: 3 | I9: 46305 | J9: =E9*F9*H9+G9+E9 -> 68200
A10: L009 | B10: A009 | C10: C009 | D10: 45850 | E10: 80000 | F10: =48%/12 -> 0.04 | G10: 2000 | H10: 3 | I10: 46306 | J10: =E10*F10*H10+G10+E10 -> 91600
A11: L010 | B11: A010 | C11: C010 | D11: 45851 | E11: 100000 | F11: =48%/12 -> 0.04 | G11: 3000 | H11: 3 | I11: 46307 | J11: =E11*F11*H11+G11+E11 -> 115000
A12: L011 | B12: A011 | C12: C011 | D12: 45852 | E12: 120000 | F12: =48%/12 -> 0.04 | G12: 3000 | H12: 3 | I12: 46308 | J12: =E12*F12*H12+G12+E12 -> 137400 | K12: =J12/H12 -> 45800
A13: L012 | B13: A012 | C13: C012 | D13: 45853 | E13: 140000 | F13: =48%/12 -> 0.04 | G13: 3000 | H13: 3 | I13: 46309 | J13: =E13*F13*H13+G13+E13 -> 159800
A14: L013 | B14: A013 | C14: C013 | D14: 45854 | E14: 160000 | F14: =48%/12 -> 0.04 | G14: 5000 | H14: 3 | I14: 46310 | J14: =E14*F14*H14+G14+E14 -> 184200
A15: L014 | B15: A014 | C15: C014 | D15: 45855 | E15: 180000 | F15: =48%/12 -> 0.04 | G15: 5000 | H15: 3 | I15: 46311 | J15: =E15*F15*H15+G15+E15 -> 206600
A16: L015 | B16: A015 | C16: C015 | D16: 45856 | E16: 200000 | F16: =48%/12 -> 0.04 | G16: 5000 | H16: 3 | I16: 46312 | J16: =E16*F16*H16+G16+E16 -> 229000
A17: L016 | B17: A016 | C17: C016 | D17: 45857 | E17: 70000 | F17: =48%/12 -> 0.04 | G17: 2000 | H17: 3 | I17: 46313 | J17: =E17*F17*H17+G17+E17 -> 80400
A18: L017 | B18: A017 | C18: C017 | D18: 45858 | E18: 90000 | F18: =48%/12 -> 0.04 | G18: 2000 | H18: 3 | I18: 46314 | J18: =E18*F18*H18+G18+E18 -> 102800
A19: L018 | B19: A018 | C19: C018 | D19: 45859 | E19: 110000 | F19: =48%/12 -> 0.04 | G19: 3000 | H19: 3 | I19: 46315 | J19: =E19*F19*H19+G19+E19 -> 126200
A20: L019 | B20: A019 | C20: C019 | D20: 45860 | E20: 50000 | F20: =48%/12 -> 0.04 | G20: 1000 | H20: 3 | I20: 46316 | J20: =E20*F20*H20+G20+E20 -> 57000
A21: L020 | B21: A020 | C21: C020 | D21: 45861 | E21: 75000 | F21: =48%/12 -> 0.04 | G21: 1000 | H21: 3 | I21: 46317 | J21: =E21*F21*H21+G21+E21 -> 85000

Sheet Installment
A1: loan_id | B1: inst_no | C1: due_date | D1: amount_due | E1: payment_date | F1: Scenario | G1: Payment_amount | H1: outstanding | I1: cumulative_due | J1: cumulative_paid | K1: cumulative_arrears_amount | L1: Oldest Unpaid Due Date | M1: DPD | N1: Bucket | O1: reporting_date
A2: L001 | B2: 1 | C2: 45871 | D2: =Loan!J2/Loan!H2 -> 19000 | E2: 45871 | F2: On-time | G2: =D2 -> 19000 | H2: =MAX(0,G2-D2) -> 0 | I2: =SUMIFS(D2:D2,A2:A2,A2) -> 19000 | J2: =G2 -> 19000 | K2: =I2-J2 -> 0 | L2: 0 | M2: =MAX(0,L43-Table1[[#This Row],[due_date]]) -> 0 | N2: =IF(M2="","Current",IF(M2<=0,"Current",IF(M2<=7,"1–7",IF(M2<=30,"8–30",IF(M2<=60,"31–60",IF(M2<=90,"61–90","90+")))))) -> Current | O2: 45969
A3: L001 | B3: 2 | C3: 45902 | D3: =Loan!J2/Loan!H2 -> 19000 | E3: 45902 | F3: On-time | G3: =D3 -> 19000 | H3: =MAX(0,D3-G3) -> 0 | I3: =SUMIFS(D2:D3,A2:A3,A3) -> 38000 | J3: =G2+G3 -> 38000 | K3: =I3-J3 -> 0 | L3: 0 | M3: =MAX(0,L44-Table1[[#This Row],[due_date]]) -> 0 | N3: =IF(M3="","Current",IF(M3<=0,"Current",IF(M3<=7,"1–7",IF(M3<=30,"8–30",IF(M3<=60,"31–60",IF(M3<=90,"61–90","90+")))))) -> Current | O3: 45970
A4: L001 | B4: 3 | C4: 45932 | D4: =Loan!J2/Loan!H2 -> 19000 | E4: 45932 | F4: On-time | G4: =D4 -> 19000 | H4: =MAX(0,D4-G4) -> 0 | I4: =SUMIFS(D2:D4,A2:A4,A4) -> 57000 | J4: =G2+G3+G4 -> 57000 | K4: =I4-J4 -> 0 | L4: 0 | M4: =MAX(0,L45-Table1[[#This Row],[due_date]]) -> 0 | N4: =IF(M4="","Current",IF(M4<=0,"Current",IF(M4<=7,"1–7",IF(M4<=30,"8–30",IF(M4<=60,"31–60",IF(M4<=90,"61–90","90+")))))) -> Current | O4: 45971
A5: L002 | B5: 1 | C5: 45903 | D5: =Loan!J3/Loan!H3 -> 27133.333 | E5: 45903 | F5: On-time | G5: =D5 -> 27133.333 | H5: =MAX(0,D5-G5) -> 0 | I5: =SUMIFS(D5:D5,A5,A5:A5) -> 27133.333 | J5: =Table1[[#This Row],[cumulative_due]] -> 27133.333 | K5: =Table1[[#This Row],[cumulative_due]]-Table1[[#This Row],[cumulative_paid]] -> 0 | L5: 0 | M5: =MAX(0,L46-Table1[[#This Row],[due_date]]) -> 0 | N5: =IF(M5="","Current",IF(M5<=0,"Current",IF(M5<=7,"1–7",IF(M5<=30,"8–30",IF(M5<=60,"31–60",IF(M5<=90,"61–90","90+")))))) -> Current | O5: 45972
A6: L002 | B6: 2 | C6: 45933 | D6: =D5 -> 27133.333 | E6: 45933 | F6: On-time | G6: =D6 -> 27133.333 | H6: =MAX(0,D6-G6) -> 0 | I6: =SUMIFS(D5:D6,A5:A6,A5) -> 54266.667 | J6: =Table1[[#This Row],[cumulative_due]] -> 54266.667 | K6: =Table1[[#This Row],[cumulative_due]]-Table1[[#This Row],[cumulative_paid]] -> 0 | L6: 0 | M6: =MAX(0,L47-Table1[[#This Row],[due_date]]) -> 0 | N6: =IF(M6="","Current",IF(M6<=0,"Current",IF(M6<=7,"1–7",IF(M6<=30,"8–30",IF(M6<=60,"31–60",IF(M6<=90,"61–90","90+")))))) -> Current | O6: 45973
A7: L002 | B7: 3 | C7: 45964 | D7: =D5 -> 27133.333 | E7: 45964 | F7: On-time | G7: =D7 -> 27133.333 | H7: =MAX(0,D7-G7) -> 0 | I7: =SUMIFS(D5:D7,A5:A7,A7) -> 81400 | J7: =Table1[[#This Row],[cumulative_due]] -> 81400 | K7: =Table1[[#This Row],[cumulative_due]]-Table1[[#This Row],[cumulative_paid]] -> 0 | L7: 0 | M7: =MAX(0,L48-Table1[[#This Row],[due_date]]) -> 0 | N7: =IF(M7="","Current",IF(M7<=0,"Current",IF(M7<=7,"1–7",IF(M7<=30,"8–30",IF(M7<=60,"31–60",IF(M7<=90,"61–90","90+")))))) -> Current | O7: 45974
A8: L003 | B8: 1 | C8: 45873 | D8: =Loan!J4/Loan!H4 -> 32666.667 | E8: 45873 | F8: Partial | G8: 13000 | H8: =D8-G8 -> 19666.667 | I8: =SUMIFS(D8:D8,A8:A8,A8) -> 32666.667 | J8: =G8 -> 13000 | K8: =I8-J8 -> 19666.667 | M8: =MAX(0,L62-Table1[[#This Row],[due_date]]) -> 0 | N8: =IF(M8="","Current",IF(M8<=0,"Current",IF(M8<=7,"1–7",IF(M8<=30,"8–30",IF(M8<=60,"31–60",IF(M8<=90,"61–90","90+")))))) -> Current | O8: 45975
A9: L003 | B9: 2 | C9: 45904 | D9: =D8 -> 32666.667 | E9: 45904 | F9: Partial | G9: 10000 | H9: =D9-G9 -> 22666.667 | I9: =SUMIFS(D8:D9,A8:A9,A9) -> 65333.333 | J9: =G8+G9 -> 23000 | K9: =I9-J9 -> 42333.333 | M9: =MAX(0,L62-Table1[[#This Row],[due_date]]) -> 0 | N9: =IF(M9="","Current",IF(M9<=0,"Current",IF(M9<=7,"1–7",IF(M9<=30,"8–30",IF(M9<=60,"31–60",IF(M9<=90,"61–90","90+")))))) -> Current | O9: 45976
A10: L003 | B10: 3 | C10: 45934 | D10: =D8 -> 32666.667 | E10: 45934 | F10: Partial | G10: 14000 | H10: =D10-G10 -> 18666.667 | I10: =SUMIFS(D8:D10,A8:A10,A10) -> 98000 | J10: =G8+G9+G10 -> 37000 | K10: =I10-J10 -> 61000 | M10: =MAX(0,L62-Table1[[#This Row],[due_date]]) -> 0 | N10: =IF(M10="","Current",IF(M10<=0,"Current",IF(M10<=7,"1–7",IF(M10<=30,"8–30",IF(M10<=60,"31–60",IF(M10<=90,"61–90","90+")))))) -> Current | O10: 45977
A11: L004 | B11: 1 | C11: 45937 | D11: =Loan!J5/Loan!H5 -> 42066.667 | E11: Null | F11: Missed | G11: 0 | H11: =D11-G11 -> 42066.667 | I11: =SUMIFS(D11:D11,A11:A11,A11) -> 42066.667 | J11: =G11 -> 0 | K11: =I11-J11 -> 42066.667 | M11: =MAX(0,L62-Table1[[#This Row],[due_date]]) -> 0 | N11: =IF(M11="","Current",IF(M11<=0,"Current",IF(M11<=7,"1–7",IF(M11<=30,"8–30",IF(M11<=60,"31–60",IF(M11<=90,"61–90","90+")))))) -> Current | O11: 45978
A12: L004 | B12: 2 | C12: 45968 | D12: =D11 -> 42066.667 | E12: Null | F12: Missed | G12: 0 | H12: =D12-G12 -> 42066.667 | I12: =SUMIFS(D11:D12,A11:A12,A12) -> 84133.333 | J12: =G12 -> 0 | K12: =I12-J12 -> 84133.333 | M12: =MAX(0,L65-Table1[[#This Row],[due_date]]) -> 0 | N12: =IF(M12="","Current",IF(M12<=0,"Current",IF(M12<=7,"1–7",IF(M12<=30,"8–30",IF(M12<=60,"31–60",IF(M12<=90,"61–90","90+")))))) -> Current | O12: 45979
A13: L004 | B13: 3 | C13: 45998 | D13: =D11 -> 42066.667 | E13: Null | F13: Missed | G13: 0 | H13: =D13-G13 -> 42066.667 | I13: =SUMIFS(D11:D13,A11:A13,A13) -> 126200 | J13: =G13 -> 0 | K13: =I13-J13 -> 126200 | M13: =MAX(0,L66-Table1[[#This Row],[due_date]]) -> 52 | N13: =IF(M13="","Current",IF(M13<=0,"Current",IF(M13<=7,"1–7",IF(M13<=30,"8–30",IF(M13<=60,"31–60",IF(M13<=90,"61–90","90+")))))) -> 31–60 | O13: 45980
A14: L005 | B14: 1 | C14: 45969 | D14: =Loan!J6/Loan!H6 -> 49533.333 | E14: 45938 | F14: Prepaid | G14: =D14 -> 49533.333 | H14: =MAX(0,D14-I14) -> 0 | I14: =SUMIFS(D14:D14,A14:A14,A14) -> 49533.333 | J14: =I14 -> 49533.333 | K14: =Table1[[#This Row],[cumulative_due]]-Table1[[#This Row],[cumulative_paid]] -> 0 | M14: =MAX(0,L67-Table1[[#This Row],[due_date]]) -> 0 | N14: =IF(M14="","Current",IF(M14<=0,"Current",IF(M14<=7,"1–7",IF(M14<=30,"8–30",IF(M14<=60,"31–60",IF(M14<=90,"61–90","90+")))))) -> Current | O14: 45981
A15: L005 | B15: 2 | C15: 45999 | D15: =D14 -> 49533.333 | E15: 45969 | F15: Prepaid | G15: =D15 -> 49533.333 | H15: =MAX(0,D15-I15) -> 0 | I15: =SUMIFS(D15:D16,A15:A16,A15) -> 99066.667 | J15: =I15 -> 99066.667 | K15: =Table1[[#This Row],[cumulative_due]]-Table1[[#This Row],[cumulative_paid]] -> 0 | M15: =MAX(0,L68-Table1[[#This Row],[due_date]]) -> 0 | N15: =IF(M15="","Current",IF(M15<=0,"Current",IF(M15<=7,"1–7",IF(M15<=30,"8–30",IF(M15<=60,"31–60",IF(M15<=90,"61–90","90+")))))) -> Current | O15: 45982
A16: L005 | B16: 3 | C16: 46030 | D16: =D15 -> 49533.333 | E16: 45999 | F16: Prepaid | G16: =D16 -> 49533.333 | H16: =MAX(0,D16-I16) -> 0 | I16: =SUMIFS(D14:D16,A14:A16,A16) -> 148600 | J16: =I16 -> 148600 | K16: =Table1[[#This Row],[cumulative_due]]-Table1[[#This Row],[cumulative_paid]] -> 0 | M16: =MAX(0,L69-Table1[[#This Row],[due_date]]) -> 0 | N16: =IF(M16="","Current",IF(M16<=0,"Current",IF(M16<=7,"1–7",IF(M16<=30,"8–30",IF(M16<=60,"31–60",IF(M16<=90,"61–90","90+")))))) -> Current | O16: 45983
A17: L006 | B17: 1 | C17: 45878 | D17: =Loan!J7/Loan!H7 -> 57666.667 | E17: Null | F17: Missed | G17: 0 | H17: =D17-G17 -> 57666.667 | I17: =SUMIFS(D15:D17,A15:A17,A17) -> 57666.667 | J17: =MAX(0,G17-I17) -> 0 | K17: =I17-J17 -> 57666.667 | M17: =MAX(0,L70-Table1[[#This Row],[due_date]]) -> 0 | N17: =IF(M17="","Current",IF(M17<=0,"Current",IF(M17<=7,"1–7",IF(M17<=30,"8–30",IF(M17<=60,"31–60",IF(M17<=90,"61–90","90+")))))) -> Current | O17: 45984
A18: L006 | B18: 2 | C18: 45909 | D18: =Loan!J7/Loan!H7 -> 57666.667 | E18: 45909 | F18: Cured | G18: =H17+D18 -> 115333.33 | H18: =Table1[[#This Row],[Payment_amount]]-D17-Table1[[#This Row],[amount_due]] -> 0 | I18: =SUMIFS(D16:D18,A16:A18,A18) -> 115333.33 | J18: =Table1[[#This Row],[cumulative_due]] -> 115333.33 | K18: =Table1[[#This Row],[cumulative_due]]-Table1[[#This Row],[cumulative_paid]] -> 0 | M18: =MAX(0,L71-Table1[[#This Row],[due_date]]) -> 0 | N18: =IF(M18="","Current",IF(M18<=0,"Current",IF(M18<=7,"1–7",IF(M18<=30,"8–30",IF(M18<=60,"31–60",IF(M18<=90,"61–90","90+")))))) -> Current | O18: 45985
A19: L006 | B19: 3 | C19: 45939 | D19: =Loan!J7/Loan!H7 -> 57666.667 | E19: 46000 | F19: Late | G19: =Table1[[#This Row],[amount_due]] -> 57666.667 | H19: =Table1[[#This Row],[amount_due]]-Table1[[#This Row],[Payment_amount]] -> 0 | I19: =SUMIFS(D17:D19,A17:A19,A19) -> 173000 | J19: =Table1[[#This Row],[cumulative_due]] -> 173000 | K19: =Table1[[#This Row],[cumulative_due]]-Table1[[#This Row],[cumulative_paid]] -> 0 | N19: =IF(M19="","Current",IF(M19<=0,"Current",IF(M19<=7,"1–7",IF(M19<=30,"8–30",IF(M19<=60,"31–60",IF(M19<=90,"61–90","90+")))))) -> Current | O19: 45986
A20: L007 | B20: 1 | C20: 45879 | D20: =Loan!J8/Loan!H8 -> 64300 | E20: 45879 | F20: On-time | G20: =D20 -> 64300 | H20: =MAX(0,I20-D20) -> 0 | I20: =SUMIFS(D18:D20,A18:A20,A20) -> 64300 | J20: =Table1[[#This Row],[cumulative_due]] -> 64300 | K20: =Table1[[#This Row],[cumulative_due]]-Table1[[#This Row],[cumulative_paid]] -> 0 | L20: 0 | M20: =MAX(0,L61-Table1[[#This Row],[due_date]]) -> 0 | N20: =IF(M20="","Current",IF(M20<=0,"Current",IF(M20<=7,"1–7",IF(M20<=30,"8–30",IF(M20<=60,"31–60",IF(M20<=90,"61–90","90+")))))) -> Current | O20: 45987
A21: L007 | B21: 2 | C21: 45910 | D21: =D20 -> 64300 | E21: 45910 | F21: On-time | G21: =D21 -> 64300 | H21: =MAX(0,G21-D21) -> 0 | I21: =SUMIFS(D19:D21,A19:A21,A21) -> 128600 | J21: =Table1[[#This Row],[cumulative_due]] -> 128600 | K21: =Table1[[#This Row],[cumulative_due]]-Table1[[#This Row],[cumulative_paid]] -> 0 | L21: 0 | M21: =MAX(0,L62-Table1[[#This Row],[due_date]]) -> 0 | N21: =IF(M21="","Current",IF(M21<=0,"Current",IF(M21<=7,"1–7",IF(M21<=30,"8–30",IF(M21<=60,"31–60",IF(M21<=90,"61–90","90+")))))) -> Current | O21: 45988
A22: L007 | B22: 3 | C22: 45940 | D22: =D21 -> 64300 | E22: 45940 | F22: On-time | G22: =D22 -> 64300 | H22: =MAX(0,G22-D22) -> 0 | I22: =SUMIFS(D20:D22,A20:A22,A22) -> 192900 | J22: =Table1[[#This Row],[cumulative_due]] -> 192900 | K22: =Table1[[#This Row],[cumulative_due]]-Table1[[#This Row],[cumulative_paid]] -> 0 | L22: 0 | M22: =MAX(0,L65-Table1[[#This Row],[due_date]]) -> 0 | N22: =IF(M22="","Current",IF(M22<=0,"Current",IF(M22<=7,"1–7",IF(M22<=30,"8–30",IF(M22<=60,"31–60",IF(M22<=90,"61–90","90+")))))) -> Current | O22: 45989
A23: L008 | B23: 1 | C23: 45880 | D23: =Loan!J9/Loan!H9 -> 22733.333 | E23: 45972 | F23: Late | G23: =Table1[[#This Row],[amount_due]] -> 22733.333 | H23: =Table1[[#This Row],[Payment_amount]]-Table1[[#This Row],[amount_due]] -> 0 | I23: =SUMIFS(D21:D23,A21:A23,A23) -> 22733.333 | J23: =Table1[[#This Row],[Payment_amount]] -> 22733.333 | K23: =Table1[[#This Row],[cumulative_due]]-Table1[[#This Row],[cumulative_paid]] -> 0 | M23: =MAX(0,L66-Table1[[#This Row],[due_date]]) -> 170 | N23: =IF(M23="","Current",IF(M23<=0,"Current",IF(M23<=7,"1–7",IF(M23<=30,"8–30",IF(M23<=60,"31–60",IF(M23<=90,"61–90","90+")))))) -> 90+ | O23: 46050
A24: L008 | B24: 2 | C24: 45911 | D24: =D23 -> 22733.333 | E24: 46002 | F24: Late | G24: =Table1[[#This Row],[amount_due]] -> 22733.333 | H24: =Table1[[#This Row],[Payment_amount]]-Table1[[#This Row],[amount_due]] -> 0 | I24: =SUMIFS(D22:D24,A22:A24,A24) -> 45466.667 | J24: =G23+Table1[[#This Row],[Payment_amount]] -> 45466.667 | K24: =Table1[[#This Row],[cumulative_due]]-Table1[[#This Row],[cumulative_paid]] -> 0 | M24: =MAX(0,L66-Table1[[#This Row],[due_date]]) -> 139 | N24: =IF(M24="","Current",IF(M24<=0,"Current",IF(M24<=7,"1–7",IF(M24<=30,"8–30",IF(M24<=60,"31–60",IF(M24<=90,"61–90","90+")))))) -> 90+ | O24: 45991
A25: L008 | B25: 3 | C25: 45941 | D25: =D24 -> 22733.333 | E25: 46033 | F25: Late | G25: =Table1[[#This Row],[amount_due]] -> 22733.333 | H25: =Table1[[#This Row],[Payment_amount]]-Table1[[#This Row],[amount_due]] -> 0 | I25: =SUMIFS(D23:D25,A23:A25,A25) -> 68200 | J25: =G23+G24+Table1[[#This Row],[Payment_amount]] -> 68200 | K25: =Table1[[#This Row],[cumulative_due]]-Table1[[#This Row],[cumulative_paid]] -> 0 | M25: =MAX(0,L66-Table1[[#This Row],[due_date]]) -> 109 | N25: =IF(M25="","Current",IF(M25<=0,"Current",IF(M25<=7,"1–7",IF(M25<=30,"8–30",IF(M25<=60,"31–60",IF(M25<=90,"61–90","90+")))))) -> 90+ | O25: 45992
A26: L009 | B26: 1 | C26: 45881 | D26: =Loan!J10/Loan!H10 -> 30533.333 | E26: 45881 | F26: Partial | G26: 12000 | H26: =Table1[[#This Row],[amount_due]]-Table1[[#This Row],[Payment_amount]] -> 18533.333 | I26: =SUMIFS(D24:D26,A24:A26,A26) -> 30533.333 | J26: =Table1[[#This Row],[Payment_amount]] -> 12000 | K26: =Table1[[#This Row],[cumulative_due]]-Table1[[#This Row],[cumulative_paid]] -> 18533.333 | M26: =MAX(0,L69-Table1[[#This Row],[due_date]]) -> 0 | N26: =IF(M26="","Current",IF(M26<=0,"Current",IF(M26<=7,"1–7",IF(M26<=30,"8–30",IF(M26<=60,"31–60",IF(M26<=90,"61–90","90+")))))) -> Current | O26: 45993
A27: L009 | B27: 2 | C27: 45912 | D27: =D26 -> 30533.333 | E27: 46003 | F27: Late | G27: =Table1[[#This Row],[amount_due]] -> 30533.333 | H27: =Table1[[#This Row],[Payment_amount]]-Table1[[#This Row],[amount_due]] -> 0 | I27: =SUMIFS(D25:D27,A25:A27,A27) -> 61066.667 | J27: =G26+Table1[[#This Row],[Payment_amount]]+G2 -> 61533.333 | M27: =MAX(0,L70-Table1[[#This Row],[due_date]]) -> 0 | N27: =IF(M27="","Current",IF(M27<=0,"Current",IF(M27<=7,"1–7",IF(M27<=30,"8–30",IF(M27<=60,"31–60",IF(M27<=90,"61–90","90+")))))) -> Current | O27: 45994
A28: L009 | B28: 3 | C28: 45942 | D28: =D27 -> 30533.333 | E28: 46065 | F28: Late | G28: =Table1[[#This Row],[amount_due]] -> 30533.333 | H28: =Table1[[#This Row],[Payment_amount]]-Table1[[#This Row],[amount_due]] -> 0 | I28: =SUMIFS(D26:D28,A26:A28,A28) -> 91600 | J28: =G26+G27+Table1[[#This Row],[Payment_amount]] -> 73066.667 | M28: =MAX(0,L71-Table1[[#This Row],[due_date]]) -> 0 | N28: =IF(M28="","Current",IF(M28<=0,"Current",IF(M28<=7,"1–7",IF(M28<=30,"8–30",IF(M28<=60,"31–60",IF(M28<=90,"61–90","90+")))))) -> Current | O28: 45995
A29: L010 | B29: 1 | C29: 45882 | D29: =Loan!J11/Loan!H11 -> 38333.333 | E29: Null | F29: Missed | G29: 0 | H29: =D29-G29 -> 38333.333 | I29: =SUMIFS(D27:D29,A27:A29,A29) -> 38333.333 | J29: =G29 -> 0 | K29: =I29-J29 -> 38333.333 | M29: =MAX(0,L72-Table1[[#This Row],[due_date]]) -> 0 | N29: =IF(M29="","Current",IF(M29<=0,"Current",IF(M29<=7,"1–7",IF(M29<=30,"8–30",IF(M29<=60,"31–60",IF(M29<=90,"61–90","90+")))))) -> Current | O29: 45996
A30: L010 | B30: 2 | C30: 45913 | D30: =D29 -> 38333.333 | E30: Null | F30: Missed | G30: 0 | H30: =D30-G30 -> 38333.333 | I30: =SUMIFS(D28:D30,A28:A30,A30) -> 76666.667 | J30: =G30 -> 0 | K30: =I30-J30 -> 76666.667 | M30: =MAX(0,L73-Table1[[#This Row],[due_date]]) -> 0 | N30: =IF(M30="","Current",IF(M30<=0,"Current",IF(M30<=7,"1–7",IF(M30<=30,"8–30",IF(M30<=60,"31–60",IF(M30<=90,"61–90","90+")))))) -> Current | O30: 45997
A31: L010 | B31: 3 | C31: 45943 | D31: =D30 -> 38333.333 | E31: Null | F31: Missed | G31: 0 | H31: =D31-G31 -> 38333.333 | I31: =SUMIFS(D29:D31,A29:A31,A31) -> 115000 | J31: =G31 -> 0 | K31: =I31-J31 -> 115000 | M31: =MAX(0,L74-Table1[[#This Row],[due_date]]) -> 0 | N31: =IF(M31="","Current",IF(M31<=0,"Current",IF(M31<=7,"1–7",IF(M31<=30,"8–30",IF(M31<=60,"31–60",IF(M31<=90,"61–90","90+")))))) -> Current | O31: 45998
A32: L011 | B32: 1 | C32: 45883 | D32: =Loan!J12/Loan!H12 -> 45800 | E32: 45874 | F32: Prepaid | G32: =Table1[[#This Row],[amount_due]] -> 45800 | H32: =Table1[[#This Row],[amount_due]]-Table1[[#This Row],[Payment_amount]] -> 0 | I32: =SUMIFS(D30:D32,A30:A32,A32) -> 45800 | J32: =Table1[[#This Row],[Payment_amount]] -> 45800 | K32: =Table1[[#This Row],[cumulative_due]]-Table1[[#This Row],[cumulative_paid]] -> 0 | M32: =MAX(0,L75-Table1[[#This Row],[due_date]]) -> 0 | N32: =IF(M32="","Current",IF(M32<=0,"Current",IF(M32<=7,"1–7",IF(M32<=30,"8–30",IF(M32<=60,"31–60",IF(M32<=90,"61–90","90+")))))) -> Current | O32: 45999
A33: L011 | B33: 2 | C33: 45914 | D33: =D32 -> 45800 | E33: 45901 | F33: Prepaid | G33: =Table1[[#This Row],[amount_due]] -> 45800 | H33: =Table1[[#This Row],[amount_due]]-Table1[[#This Row],[Payment_amount]] -> 0 | I33: =SUMIFS(D31:D33,A31:A33,A33) -> 91600 | J33: =G32+Table1[[#This Row],[Payment_amount]] -> 91600 | K33: =Table1[[#This Row],[cumulative_due]]-Table1[[#This Row],[cumulative_paid]] -> 0 | M33: =MAX(0,L76-Table1[[#This Row],[due_date]]) -> 0 | N33: =IF(M33="","Current",IF(M33<=0,"Current",IF(M33<=7,"1–7",IF(M33<=30,"8–30",IF(M33<=60,"31–60",IF(M33<=90,"61–90","90+")))))) -> Current | O33: 46000
A34: LO11 | B34: 3 | C34: 45944 | D34: =D32 -> 45800 | E34: 45930 | F34: Prepaid | G34: =Table1[[#This Row],[amount_due]] -> 45800 | H34: =Table1[[#This Row],[amount_due]]-Table1[[#This Row],[Payment_amount]] -> 0 | I34: =D32+D33+Table1[[#This Row],[amount_due]] -> 137400 | J34: =G32+G33+Table1[[#This Row],[Payment_amount]] -> 137400 | K34: =Table1[[#This Row],[cumulative_due]]-Table1[[#This Row],[cumulative_paid]] -> 0 | M34: =MAX(0,L77-Table1[[#This Row],[due_date]]) -> 0 | N34: =IF(M34="","Current",IF(M34<=0,"Current",IF(M34<=7,"1–7",IF(M34<=30,"8–30",IF(M34<=60,"31–60",IF(M34<=90,"61–90","90+")))))) -> Current | O34: 46001
A35: L012 | B35: 1 | C35: 45884 | D35: =Loan!J13/Loan!H13 -> 53266.667 | E35: Null | F35: Missed | G35: 0 | H35: =Table1[[#This Row],[amount_due]]-Table1[[#This Row],[Payment_amount]] -> 53266.667 | I35: =SUMIFS(D33:D35,A33:A35,A35) -> 53266.667 | J35: =Table1[[#This Row],[Payment_amount]] -> 0 | K35: =Table1[[#This Row],[cumulative_due]]-Table1[[#This Row],[cumulative_paid]] -> 53266.667 | M35: =MAX(0,L78-Table1[[#This Row],[due_date]]) -> 0 | N35: =IF(M35="","Current",IF(M35<=0,"Current",IF(M35<=7,"1–7",IF(M35<=30,"8–30",IF(M35<=60,"31–60",IF(M35<=90,"61–90","90+")))))) -> Current | O35: 46002
A36: L012 | B36: 2 | C36: 45915 | D36: =D35 -> 53266.667 | E36: 45915 | F36: Cured | G36: =H35+D37 -> 106533.33 | H36: =Table1[[#This Row],[Payment_amount]]-I36 -> 0 | I36: =SUMIFS(D34:D36,A34:A36,A36) -> 106533.33 | J36: =Table1[[#This Row],[Payment_amount]] -> 106533.33 | K36: =Table1[[#This Row],[cumulative_due]]-Table1[[#This Row],[cumulative_paid]] -> 0 | M36: =MAX(0,L79-Table1[[#This Row],[due_date]]) -> 0 | N36: =IF(M36="","Current",IF(M36<=0,"Current",IF(M36<=7,"1–7",IF(M36<=30,"8–30",IF(M36<=60,"31–60",IF(M36<=90,"61–90","90+")))))) -> Current | O36: 46003
A37: L012 | B37: 3 | C37: 45945 | D37: =D36 -> 53266.667 | E37: 46006 | F37: Late | G37: =Table1[[#This Row],[amount_due]] -> 53266.667 | H37: =Table1[[#This Row],[Payment_amount]]-Table1[[#This Row],[amount_due]] -> 0 | I37: =SUMIFS(D35:D37,A35:A37,A37) -> 159800 | J37: =G36+Table1[[#This Row],[Payment_amount]] -> 159800 | K37: =Table1[[#This Row],[cumulative_due]]-Table1[[#This Row],[cumulative_paid]] -> 0 | M37: =MAX(0,L80-Table1[[#This Row],[due_date]]) -> 0 | N37: =IF(M37="","Current",IF(M37<=0,"Current",IF(M37<=7,"1–7",IF(M37<=30,"8–30",IF(M37<=60,"31–60",IF(M37<=90,"61–90","90+")))))) -> Current | O37: 46004
A38: L013 | B38: 1 | C38: 45885 | D38: =Loan!J14/Loan!H14 -> 61400 | E38: 45885 | F38: On-time | G38: =Table1[[#This Row],[amount_due]] -> 61400 | H38: =Table1[[#This Row],[Payment_amount]]-Table1[[#This Row],[amount_due]] -> 0 | I38: =SUMIFS(D36:D38,A36:A38,A38) -> 61400 | J38: =Table1[[#This Row],[cumulative_due]] -> 61400 | K38: =Table1[[#This Row],[cumulative_due]]-Table1[[#This Row],[cumulative_paid]] -> 0 | L38: 0 | M38: =MAX(0,L81-Table1[[#This Row],[due_date]]) -> 0 | N38: =IF(M38="","Current",IF(M38<=0,"Current",IF(M38<=7,"1–7",IF(M38<=30,"8–30",IF(M38<=60,"31–60",IF(M38<=90,"61–90","90+")))))) -> Current | O38: 46005
A39: L013 | B39: 2 | C39: 45916 | D39: =D38 -> 61400 | E39: 45916 | F39: On-time | G39: =Table1[[#This Row],[amount_due]] -> 61400 | H39: =Table1[[#This Row],[Payment_amount]]-Table1[[#This Row],[amount_due]] -> 0 | I39: =SUMIFS(D37:D39,A37:A39,A39) -> 122800 | J39: =Table1[[#This Row],[cumulative_due]] -> 122800 | K39: =Table1[[#This Row],[cumulative_due]]-Table1[[#This Row],[cumulative_paid]] -> 0 | L39: 0 | M39: =MAX(0,L82-Table1[[#This Row],[due_date]]) -> 0 | N39: =IF(M39="","Current",IF(M39<=0,"Current",IF(M39<=7,"1–7",IF(M39<=30,"8–30",IF(M39<=60,"31–60",IF(M39<=90,"61–90","90+")))))) -> Current | O39: 46006
A40: L013 | B40: 3 | C40: 45946 | D40: =D39 -> 61400 | E40: 45946 | F40: On-time | G40: =Table1[[#This Row],[amount_due]] -> 61400 | H40: =Table1[[#This Row],[Payment_amount]]-Table1[[#This Row],[amount_due]] -> 0 | I40: =SUMIFS(D38:D40,A38:A40,A40) -> 184200 | J40: =Table1[[#This Row],[cumulative_due]] -> 184200 | K40: =Table1[[#This Row],[cumulative_due]]-Table1[[#This Row],[cumulative_paid]] -> 0 | L40: 0 | M40: =MAX(0,L83-Table1[[#This Row],[due_date]]) -> 0 | N40: =IF(M40="","Current",IF(M40<=0,"Current",IF(M40<=7,"1–7",IF(M40<=30,"8–30",IF(M40<=60,"31–60",IF(M40<=90,"61–90","90+")))))) -> Current | O40: 46007
...

Sheet Formula Allocation
A1: Formula / Rule | B1: Implementation | C1: Purpose
A2: Monthly rate | B2: Annual interest rate / 12 | C2: Converts annual nominal rate to monthly rate.
A3: Maturity date | B3: EDATE(disbursement date, term_months) | C3: Generates contractual maturity date without hard-coding.
A4: Instalment due | B4: Principal+ interest+ processing fee/term | C4: Flat-rate scheduled instalment; processing fee is tracked separately.
A5: Cumulative due | B5: SUMIFS(amount_due, loan_id, current loan, instalment no <= current) | C5: Tracks the contractual amount due up to each instalment.
A6: Payments to reporting date | B6: SUMIFS(payment_amount, loan_id, current loan, payment_date <= reporting date) | C6: Prevents future payments from affecting DPD.
A7: FIFO allocation | B7: MAX(0, MIN(current amount due, total paid - prior cumulative due)) | C7: Applies payments to the oldest unpaid instalment first.
A8: Arrears | B8: MAX(0, cumulative due - cumulative allocated payment) | C8: Shows unpaid contractual amount.
A9: Oldest unpaid due date | B9: MINIFS(due_date where arrears > 0) | C9: Identifies the earliest outstanding obligation.
A10: DPD | B10: MAX(0, reporting date - oldest unpaid due date) | C10: Measures days past due; never negative.
A11: Bucket | B11: Current / 1–7 / 8–30 / 31–60 / 61–90 / 90+ | C11: Standardises delinquency segmentation.

Sheet Metric
A1: Metric / Field | B1: Definition | C1: Formula (plain language)
A2: Reporting Date | B2: The as-of date the whole dashboard is evaluated against. Only payments made on/before this date count as collected; only instalments due on/before this date count as due. | C2: Dashboard!C6 (user input)
A3: Loans Disbursed | B3: Count of loans whose disbursement date is on/before the Reporting Date, within the selected filters. | C3: COUNT loans WHERE disbursement_date ≤ Reporting Date AND filters match
A4: Active Accounts | B4: Loans disbursed by the Reporting Date that still carry an outstanding principal balance greater than zero. Source data has no explicit account-status field, so this is inferred from balance, not a system status flag. | C4: COUNT loans WHERE outstanding_principal > 0 AND disbursed
A5: Outstanding Principal | B5: Principal not yet recovered, estimated pro-rata from cumulative payments received against the loan's total contract value (principal+interest+fees), because the source Installment data gives only a blended instalment amount, not a principal/interest split. | C5: Principal × (1 − cumulative allocated payments ÷ total contract amount)
A6: Amount Due (to date) | B6: Contractual amount that has fallen due as of the Reporting Date (instalments with due_date ≤ Reporting Date), summed across in-scope loans. | C6: SUM(amount_due) WHERE due_date ≤ Reporting Date
A7: Amount Collected | B7: Actual cash received on/before the Reporting Date. Not capped at Amount Due, so it can exceed 100% of due where customers have prepaid. | C7: SUM(payment_amount) WHERE payment_date ≤ Reporting Date
A8: Collection Rate | B8: Amount Collected as a percentage of Amount Due. | C8: Amount Collected ÷ Amount Due
A9: Arrears (value) | B9: Contractual amount due to date that has not yet been covered by payments received. | C9: MAX(0, Amount Due to date − Amount Collected to date)
A10: Oldest Unpaid Due Date | B10: The due date of the earliest instalment not yet fully covered by payments, applying FIFO allocation (payments fill the oldest obligation first). | C10: MIN(due_date) WHERE that instalment's cumulative due exceeds cumulative payments received
A11: DPD (Days Past Due) | B11: Days between the Reporting Date and the Oldest Unpaid Due Date; 0 if the loan is fully current. | C11: MAX(0, Reporting Date − Oldest Unpaid Due Date)
A12: DPD Bucket | B12: Standard delinquency segmentation. | C12: Current (0) / 1–7 / 8–30 / 31–60 / 61–90 / 90+
... A17: Total Contract Amount | B17: Flat-rate scheduled repayment: principal + (principal × monthly rate × term) + fees. Recalculated rather than trusted from the source 'total_amount' field because one loan (L003) did not reconcile (see Reconciliation tab). | C17: Principal + (Principal × Monthly Rate × Term) + Fees

Sheet Reconcilation
A1: Check | B1: Source Value | C1: Dashboard Value
A2: Loan Count | B2: 20 | C2: 20
A3: Installment Row Count | B3: 60 | C3: 60
A4: Total principal disbursed | B4: =SUM(Loan!E2:E21) -> 2205000 | C4: =B4 -> 2205000
A5: Total contract value — flat formula (₦) | C5: =SUM(Loan!J2:J21) -> 2520300
A6: Sum of all instalment amount_due (₦) | C6: =SUM(Installment!I33:I61) -> 2637400

Sheet Dashboard
B2: Loan Repayment Dashboard
B3: Nigerian microfinance loan book — disbursements, collections & delinquency
B5: Controls
B6: Reporting Date | C6: 46050 | F6: Channel filter: source data does not currently capture acquisition_channel at customer level (see Reconciliation tab) — filter is provided for future use and defaults to 'All'.
B7: Product | C7: All
B8: Channel | C8: All
B9: Customer Type | C9: All
B11: Portfolio Snapshot
B12: ="As of "&TEXT($C$6,"dd mmm yyyy")&" | Product: "&$C$7&" | Channel: "&$C$8&" | Customer Type: "&$C$9 -> As of 28 Jan 2026 | Product: All | Channel: All | Customer Type: All
B13: Loans Disbursed | E13: Active Accounts | H13: Outstanding Principal | K13: Amount Due (to date) | N13: Amount Collected | Q13: Collection Rate
B14: =SUMPRODUCT(('[1]Calc - Loan Summary'!$J$5:$J$24=1)*(('[1]Calc - Loan Summary'!$C$5:$C$24=$C$7)+($C$7="All")>0)*(('[1]Calc - Loan Summary'!$D$5:$D$24=$C$8)+($C$8="All")>0)*(('[1]Calc - Loan Summary'!$E$5:$E$24=$C$9)+($C$9="All")>0)) -> 20 | E14: =SUMPRODUCT(('[1]Calc - Loan Summary'!$J$5:$J$24=1)*('[1]Calc - Loan Summary'!$O$5:$O$24>0)*(('[1]Calc - Loan Summary'!$C$5:$C$24=$C$7)+($C$7="All")>0)*(('[1]Calc - Loan Summary'!$D$5:$D$24=$C$8)+($C$8="All")>0)*(('[1]Calc - Loan Summary'!$E$5:$E$24=$C$9)+($C$9="All")>0)) -> 13 | H14: =SUM(Installment!H8:H61) -> 431666.67 | K14: =SUM(Installment!D2:D61) -> 2520300 | N14: =SUM(Installment!J2:J61) -> 3416466.7 | Q14: =IFERROR(N14/K14,0) -> 1.3555794
B18: Delinquency by DPD Bucket
B19: DPD Bucket | C19: Loan Count (units) | D19: % of Loans | E19: Arrears Value (₦) | F19: Outstanding Principal at Risk (₦) | G19: % of Outstanding Principal
B20: Current | C20: =SUMPRODUCT(('[1]Calc - Loan Summary'!$J$5:$J$24=1)*(('[1]Calc - Loan Summary'!$C$5:$C$24=$C$7)+($C$7="All")>0)*(('[1]Calc - Loan Summary'!$D$5:$D$24=$C$8)+($C$8="All")>0)*(('[1]Calc - Loan Summary'!$E$5:$E$24=$C$9)+($C$9="All")>0)*('[1]Calc - Loan Summary'!$R$5:$R$24=$B20)) -> 11 | D20: =IFERROR(C20/SUMPRODUCT(('[1]Calc - Loan Summary'!$J$5:$J$24=1)*(('[1]Calc - Loan Summary'!$C$5:$C$24=$C$7)+($C$7="All")>0)*(('[1]Calc - Loan Summary'!$D$5:$D$24=$C$8)+($C$8="All")>0)*(('[1]Calc - Loan Summary'!$E$5:$E$24=$C$9)+($C$9="All")>0)),0) -> 0.55 | E20: =SUMPRODUCT(('[1]Calc - Loan Summary'!$J$5:$J$24=1)*(('[1]Calc - Loan Summary'!$C$5:$C$24=$C$7)+($C$7="All")>0)*(('[1]Calc - Loan Summary'!$D$5:$D$24=$C$8)+($C$8="All")>0)*(('[1]Calc - Loan Summary'!$E$5:$E$24=$C$9)+($C$9="All")>0)*('[1]Calc - Loan Summary'!$R$5:$R$24=$B20)*'[1]Calc - Loan Summary'!$M$5:$M$24) -> 0 | F20: =SUMPRODUCT(('[1]Calc - Loan Summary'!$J$5:$J$24=1)*(('[1]Calc - Loan Summary'!$C$5:$C$24=$C$7)+($C$7="All")>0)*(('[1]Calc - Loan Summary'!$D$5:$D$24=$C$8)+($C$8="All")>0)*(('[1]Calc - Loan Summary'!$E$5:$E$24=$C$9)+($C$9="All")>0)*('[1]Calc - Loan Summary'!$R$5:$R$24=$B20)*'[1]Calc - Loan Summary'!$O$5:$O$24) -> 3.6470826e-10 | G20: =IFERROR(F20/SUMPRODUCT(('[1]Calc - Loan Summary'!$J$5:$J$24=1)*(('[1]Calc - Loan Summary'!$C$5:$C$24=$C$7)+($C$7="All")>0)*(('[1]Calc - Loan Summary'!$D$5:$D$24=$C$8)+($C$8="All")>0)*(('[1]Calc - Loan Summary'!$E$5:$E$24=$C$9)+($C$9="All")>0)*'[1]Calc - Loan Summary'!$O$5:$O$24),0) -> 5.2821057e-16
B21: 1-7 | C21: =SUMPRODUCT(('[1]Calc - Loan Summary'!$J$5:$J$24=1)*(('[1]Calc - Loan Summary'!$C$5:$C$24=$C$7)+($C$7="All")>0)*(('[1]Calc - Loan Summary'!$D$5:$D$24=$C$8)+($C$8="All")>0)*(('[1]Calc - Loan Summary'!$E$5:$E$24=$C$9)+($C$9="All")>0)*('[1]Calc - Loan Summary'!$R$5:$R$24=$B21)) -> 0 | D21: =IFERROR(C21/SUMPRODUCT(('[1]Calc - Loan Summary'!$J$5:$J$24=1)*(('[1]Calc - Loan Summary'!$C$5:$C$24=$C$7)+($C$7="All")>0)*(('[1]Calc - Loan Summary'!$D$5:$D$24=$C$8)+($C$8="All")>0)*(('[1]Calc - Loan Summary'!$E$5:$E$24=$C$9)+($C$9="All")>0)),0) -> 0 | E21: =SUMPRODUCT(('[1]Calc - Loan Summary'!$J$5:$J$24=1)*(('[1]Calc - Loan Summary'!$C$5:$C$24=$C$7)+($C$7="All")>0)*(('[1]Calc - Loan Summary'!$D$5:$D$24=$C$8)+($C$8="All")>0)*(('[1]Calc - Loan Summary'!$E$5:$E$24=$C$9)+($C$9="All")>0)*('[1]Calc - Loan Summary'!$R$5:$R$24=$B21)*'[1]Calc - Loan Summary'!$M$5:$M$24) -> 0 | F21: =SUMPRODUCT(('[1]Calc - Loan Summary'!$J$5:$J$24=1)*(('[1]Calc - Loan Summary'!$C$5:$C$24=$C$7)+($C$7="All")>0)*(('[1]Calc - Loan Summary'!$D$5:$D$24=$C$8)+($C$8="All")>0)*(('[1]Calc - Loan Summary'!$E$5:$E$24=$C$9)+($C$9="All")>0)*('[1]Calc - Loan Summary'!$R$5:$R$24=$B21)*'[1]Calc - Loan Summary'!$O$5:$O$24) -> 0 | G21: =IFERROR(F21/SUMPRODUCT(('[1]Calc - Loan Summary'!$J$5:$J$24=1)*(('[1]Calc - Loan Summary'!$C$5:$C$24=$C$7)+($C$7="All")>0)*(('[1]Calc - Loan Summary'!$D$5:$D$24=$C$8)+($C$8="All")>0)*(('[1]Calc - Loan Summary'!$E$5:$E$24=$C$9)+($C$9="All")>0)*'[1]Calc - Loan Summary'!$O$5:$O$24),0) -> 0
B22: 8-30 | C22: =SUMPRODUCT(('[1]Calc - Loan Summary'!$J$5:$J$24=1)*(('[1]Calc - Loan Summary'!$C$5:$C$24=$C$7)+($C$7="All")>0)*(('[1]Calc - Loan Summary'!$D$5:$D$24=$C$8)+($C$8="All")>0)*(('[1]Calc - Loan Summary'!$E$5:$E$24=$C$9)+($C$9="All")>0)*('[1]Calc - Loan Summary'!$R$5:$R$24=$B22)) -> 0 | D22: =IFERROR(C22/SUMPRODUCT(('[1]Calc - Loan Summary'!$J$5:$J$24=1)*(('[1]Calc - Loan Summary'!$C$5:$C$24=$C$7)+($C$7="All")>0)*(('[1]Calc - Loan Summary'!$D$5:$D$24=$C$8)+($C$8="All")>0)*(('[1]Calc - Loan Summary'!$E$5:$E$24=$C$9)+($C$9="All")>0)),0) -> 0 | E22: =SUMPRODUCT(('[1]Calc - Loan Summary'!$J$5:$J$24=1)*(('[1]Calc - Loan Summary'!$C$5:$C$24=$C$7)+($C$7="All")>0)*(('[1]Calc - Loan Summary'!$D$5:$D$24=$C$8)+($C$8="All")>0)*(('[1]Calc - Loan Summary'!$E$5:$E$24=$C$9)+($C$9="All")>0)*('[1]Calc - Loan Summary'!$R$5:$R$24=$B22)*'[1]Calc - Loan Summary'!$M$5:$M$24) -> 0 | F22: =SUMPRODUCT(('[1]Calc - Loan Summary'!$J$5:$J$24=1)*(('[1]Calc - Loan Summary'!$C$5:$C$24=$C$7)+($C$7="All")>0)*(('[1]Calc - Loan Summary'!$D$5:$D$24=$C$8)+($C$8="All")>0)*(('[1]Calc - Loan Summary'!$E$5:$E$24=$C$9)+($C$9="All")>0)*('[1]Calc - Loan Summary'!$R$5:$R$24=$B22)*'[1]Calc - Loan Summary'!$O$5:$O$24) -> 0 | G22: =IFERROR(F22/SUMPRODUCT(('[1]Calc - Loan Summary'!$J$5:$J$24=1)*(('[1]Calc - Loan Summary'!$C$5:$C$24=$C$7)+($C$7="All")>0)*(('[1]Calc - Loan Summary'!$D$5:$D$24=$C$8)+($C$8="All")>0)*(('[1]Calc - Loan Summary'!$E$5:$E$24=$C$9)+($C$9="All")>0)*'[1]Calc - Loan Summary'!$O$5:$O$24),0) -> 0
B23: 31-60 | C23: =SUMPRODUCT(('[1]Calc - Loan Summary'!$J$5:$J$24=1)*(('[1]Calc - Loan Summary'!$C$5:$C$24=$C$7)+($C$7="All")>0)*(('[1]Calc - Loan Summary'!$D$5:$D$24=$C$8)+($C$8="All")>0)*(('[1]Calc - Loan Summary'!$E$5:$E$24=$C$9)+($C$9="All")>0)*('[1]Calc - Loan Summary'!$R$5:$R$24=$B23)) -> 0 | D23: =IFERROR(C23/SUMPRODUCT(('[1]Calc - Loan Summary'!$J$5:$J$24=1)*(('[1]Calc - Loan Summary'!$C$5:$C$24=$C$7)+($C$7="All")>0)*(('[1]Calc - Loan Summary'!$D$5:$D$24=$C$8)+($C$8="All")>0)*(('[1]Calc - Loan Summary'!$E$5:$E$24=$C$9)+($C$9="All")>0)),0) -> 0 | E23: =SUMPRODUCT(('[1]Calc - Loan Summary'!$J$5:$J$24=1)*(('[1]Calc - Loan Summary'!$C$5:$C$24=$C$7)+($C$7="All")>0)*(('[1]Calc - Loan Summary'!$D$5:$D$24=$C$8)+($C$8="All")>0)*(('[1]Calc - Loan Summary'!$E$5:$E$24=$C$9)+($C$9="All")>0)*('[1]Calc - Loan Summary'!$R$5:$R$24=$B23)*'[1]Calc - Loan Summary'!$M$5:$M$24) -> 0 | F23: =SUMPRODUCT(('[1]Calc - Loan Summary'!$J$5:$J$24=1)*(('[1]Calc - Loan Summary'!$C$5:$C$24=$C$7)+($C$7="All")>0)*(('[1]Calc - Loan Summary'!$D$5:$D$24=$C$8)+($C$8="All")>0)*(('[1]Calc - Loan Summary'!$E$5:$E$24=$C$9)+($C$9="All")>0)*('[1]Calc - Loan Summary'!$R$5:$R$24=$B23)*'[1]Calc - Loan Summary'!$O$5:$O$24) -> 0 | G23: =IFERROR(F23/SUMPRODUCT(('[1]Calc - Loan Summary'!$J$5:$J$24=1)*(('[1]Calc - Loan Summary'!$C$5:$C$24=$C$7)+($C$7="All")>0)*(('[1]Calc - Loan Summary'!$D$5:$D$24=$C$8)+($C$8="All")>0)*(('[1]Calc - Loan Summary'!$E$5:$E$24=$C$9)+($C$9="All")>0)*'[1]Calc - Loan Summary'!$O$5:$O$24),0) -> 0
B24: 61-90 | C24: =SUMPRODUCT(('[1]Calc - Loan Summary'!$J$5:$J$24=1)*(('[1]Calc - Loan Summary'!$C$5:$C$24=$C$7)+($C$7="All")>0)*(('[1]Calc - Loan Summary'!$D$5:$D$24=$C$8)+($C$8="All")>0)*(('[1]Calc - Loan Summary'!$E$5:$E$24=$C$9)+($C$9="All")>0)*('[1]Calc - Loan Summary'!$R$5:$R$24=$B24)) -> 0 | D24: =IFERROR(C24/SUMPRODUCT(('[1]Calc - Loan Summary'!$J$5:$J$24=1)*(('[1]Calc - Loan Summary'!$C$5:$C$24=$C$7)+($C$7="All")>0)*(('[1]Calc - Loan Summary'!$D$5:$D$24=$C$8)+($C$8="All")>0)*(('[1]Calc - Loan Summary'!$E$5:$E$24=$C$9)+($C$9="All")>0)),0) -> 0 | E24: =SUMPRODUCT(('[1]Calc - Loan Summary'!$J$5:$J$24=1)*(('[1]Calc - Loan Summary'!$C$5:$C$24=$C$7)+($C$7="All")>0)*(('[1]Calc - Loan Summary'!$D$5:$D$24=$C$8)+($C$8="All")>0)*(('[1]Calc - Loan Summary'!$E$5:$E$24=$C$9)+($C$9="All")>0)*('[1]Calc - Loan Summary'!$R$5:$R$24=$B24)*'[1]Calc - Loan Summary'!$M$5:$M$24) -> 0 | F24: =SUMPRODUCT(('[1]Calc - Loan Summary'!$J$5:$J$24=1)*(('[1]Calc - Loan Summary'!$C$5:$C$24=$C$7)+($C$7="All")>0)*(('[1]Calc - Loan Summary'!$D$5:$D$24=$C$8)+($C$8="All")>0)*(('[1]Calc - Loan Summary'!$E$5:$E$24=$C$9)+($C$9="All")>0)*('[1]Calc - Loan Summary'!$R$5:$R$24=$B24)*'[1]Calc - Loan Summary'!$O$5:$O$24) -> 0 | G24: =IFERROR(F24/SUMPRODUCT(('[1]Calc - Loan Summary'!$J$5:$J$24=1)*(('[1]Calc - Loan Summary'!$C$5:$C$24=$C$7)+($C$7="All")>0)*(('[1]Calc - Loan Summary'!$D$5:$D$24=$C$8)+($C$8="All")>0)*(('[1]Calc - Loan Summary'!$E$5:$E$24=$C$9)+($C$9="All")>0)*'[1]Calc - Loan Summary'!$O$5:$O$24),0) -> 0
B25: 90+ | C25: =SUMPRODUCT(('[1]Calc - Loan Summary'!$J$5:$J$24=1)*(('[1]Calc - Loan Summary'!$C$5:$C$24=$C$7)+($C$7="All")>0)*(('[1]Calc - Loan Summary'!$D$5:$D$24=$C$8)+($C$8="All")>0)*(('[1]Calc - Loan Summary'!$E$5:$E$24=$C$9)+($C$9="All")>0)*('[1]Calc - Loan Summary'!$R$5:$R$24=$B25)) -> 9 | D25: =IFERROR(C25/SUMPRODUCT(('[1]Calc - Loan Summary'!$J$5:$J$24=1)*(('[1]Calc - Loan Summary'!$C$5:$C$24=$C$7)+($C$7="All")>0)*(('[1]Calc - Loan Summary'!$D$5:$D$24=$C$8)+($C$8="All")>0)*(('[1]Calc - Loan Summary'!$E$5:$E$24=$C$9)+($C$9="All")>0)),0) -> 0.45 | E25: =SUM(Installment!K4:K61) -> 734866.67 | F25: =SUM(Table1[outstanding]) -> 431666.67 | G25: =IFERROR(F25/SUMPRODUCT(('[1]Calc - Loan Summary'!$J$5:$J$24=1)*(('[1]Calc - Loan Summary'!$C$5:$C$24=$C$7)+($C$7="All")>0)*(('[1]Calc - Loan Summary'!$D$5:$D$24=$C$8)+($C$8="All")>0)*(('[1]Calc - Loan Summary'!$E$5:$E$24=$C$9)+($C$9="All")>0)*'[1]Calc - Loan Summary'!$O$5:$O$24),0) -> 0.62518708
B26: Total | C26: =SUM(C20:C25) -> 20 | D26: =SUM(D20:D25) -> 1 | E26: =SUM(E20:E25) -> 734866.67 | F26: =SUM(F20:F25) -> 431666.67 | G26: =SUM(G20:G25) -> 0.62518708
B28: Exposure by Product & Origination Month
B29: Origination Month | C29: Business Loan | D29: Personal Loan | E29: Salary Advance | F29: Total
B30: 2025-07 | C30: =SUMPRODUCT(('[1]Calc - Loan Summary'!$J$5:$J$24=1)*(('[1]Calc - Loan Summary'!$C$5:$C$24=$C$7)+($C$7="All")>0)*(('[1]Calc - Loan Summary'!$D$5:$D$24=$C$8)+($C$8="All")>0)*(('[1]Calc - Loan Summary'!$E$5:$E$24=$C$9)+($C$9="All")>0)*('[1]Calc - Loan Summary'!$G$5:$G$24=$B30)*('[1]Calc - Loan Summary'!$C$5:$C$24="Business Loan")*'[1]Calc - Loan Summary'!$H$5:$H$24) -> 530000 | D30: =SUMPRODUCT(('[1]Calc - Loan Summary'!$J$5:$J$24=1)*(('[1]Calc - Loan Summary'!$C$5:$C$24=$C$7)+($C$7="All")>0)*(('[1]Calc - Loan Summary'!$D$5:$D$24=$C$8)+($C$8="All")>0)*(('[1]Calc - Loan Summary'!$E$5:$E$24=$C$9)+($C$9="All")>0)*('[1]Calc - Loan Summary'!$G$5:$G$24=$B30)*('[1]Calc - Loan Summary'!$C$5:$C$24="Personal Loan")*'[1]Calc - Loan Summary'!$H$5:$H$24) -> 935000 | E30: =SUMPRODUCT(('[1]Calc - Loan Summary'!$J$5:$J$24=1)*(('[1]Calc - Loan Summary'!$C$5:$C$24=$C$7)+($C$7="All")>0)*(('[1]Calc - Loan Summary'!$D$5:$D$24=$C$8)+($C$8="All")>0)*(('[1]Calc - Loan Summary'!$E$5:$E$24=$C$9)+($C$9="All")>0)*('[1]Calc - Loan Summary'!$G$5:$G$24=$B30)*('[1]Calc - Loan Summary'!$C$5:$C$24="Salary Advance")*'[1]Calc - Loan Summary'!$H$5:$H$24) -> 430000 | F30: =SUM(C30:E30) -> 1895000
B31: 2025-08 | C31: =SUMPRODUCT(('[1]Calc - Loan Summary'!$J$5:$J$24=1)*(('[1]Calc - Loan Summary'!$C$5:$C$24=$C$7)+($C$7="All")>0)*(('[1]Calc - Loan Summary'!$D$5:$D$24=$C$8)+($C$8="All")>0)*(('[1]Calc - Loan Summary'!$E$5:$E$24=$C$9)+($C$9="All")>0)*('[1]Calc - Loan Summary'!$G$5:$G$24=$B31)*('[1]Calc - Loan Summary'!$C$5:$C$24="Business Loan")*'[1]Calc - Loan Summary'!$H$5:$H$24) -> 0 | D31: =SUMPRODUCT(('[1]Calc - Loan Summary'!$J$5:$J$24=1)*(('[1]Calc - Loan Summary'!$C$5:$C$24=$C$7)+($C$7="All")>0)*(('[1]Calc - Loan Summary'!$D$5:$D$24=$C$8)+($C$8="All")>0)*(('[1]Calc - Loan Summary'!$E$5:$E$24=$C$9)+($C$9="All")>0)*('[1]Calc - Loan Summary'!$G$5:$G$24=$B31)*('[1]Calc - Loan Summary'!$C$5:$C$24="Personal Loan")*'[1]Calc - Loan Summary'!$H$5:$H$24) -> 0 | E31: =SUMPRODUCT(('[1]Calc - Loan Summary'!$J$5:$J$24=1)*(('[1]Calc - Loan Summary'!$C$5:$C$24=$C$7)+($C$7="All")>0)*(('[1]Calc - Loan Summary'!$D$5:$D$24=$C$8)+($C$8="All")>0)*(('[1]Calc - Loan Summary'!$E$5:$E$24=$C$9)+($C$9="All")>0)*('[1]Calc - Loan Summary'!$G$5:$G$24=$B31)*('[1]Calc - Loan Summary'!$C$5:$C$24="Salary Advance")*'[1]Calc - Loan Summary'!$H$5:$H$24) -> 70000 | F31: =SUM(C31:E31) -> 70000
B32: 2025-09 | C32: =SUMPRODUCT(('[1]Calc - Loan Summary'!$J$5:$J$24=1)*(('[1]Calc - Loan Summary'!$C$5:$C$24=$C$7)+($C$7="All")>0)*(('[1]Calc - Loan Summary'!$D$5:$D$24=$C$8)+($C$8="All")>0)*(('[1]Calc - Loan Summary'!$E$5:$E$24=$C$9)+($C$9="All")>0)*('[1]Calc - Loan Summary'!$G$5:$G$24=$B32)*('[1]Calc - Loan Summary'!$C$5:$C$24="Business Loan")*'[1]Calc - Loan Summary'!$H$5:$H$24) -> 110000 | D32: =SUMPRODUCT(('[1]Calc - Loan Summary'!$J$5:$J$24=1)*(('[1]Calc - Loan Summary'!$C$5:$C$24=$C$7)+($C$7="All")>0)*(('[1]Calc - Loan Summary'!$D$5:$D$24=$C$8)+($C$8="All")>0)*(('[1]Calc - Loan Summary'!$E$5:$E$24=$C$9)+($C$9="All")>0)*('[1]Calc - Loan Summary'!$G$5:$G$24=$B32)*('[1]Calc - Loan Summary'!$C$5:$C$24="Personal Loan")*'[1]Calc - Loan Summary'!$H$5:$H$24) -> 0 | E32: =SUMPRODUCT(('[1]Calc - Loan Summary'!$J$5:$J$24=1)*(('[1]Calc - Loan Summary'!$C$5:$C$24=$C$7)+($C$7="All")>0)*(('[1]Calc - Loan Summary'!$D$5:$D$24=$C$8)+($C$8="All")>0)*(('[1]Calc - Loan Summary'!$E$5:$E$24=$C$9)+($C$9="All")>0)*('[1]Calc - Loan Summary'!$G$5:$G$24=$B32)*('[1]Calc - Loan Summary'!$C$5:$C$24="Salary Advance")*'[1]Calc - Loan Summary'!$H$5:$H$24) -> 0 | F32: =SUM(C32:E32) -> 110000
B33: 2025-10 | C33: =SUMPRODUCT(('[1]Calc - Loan Summary'!$J$5:$J$24=1)*(('[1]Calc - Loan Summary'!$C$5:$C$24=$C$7)+($C$7="All")>0)*(('[1]Calc - Loan Summary'!$D$5:$D$24=$C$8)+($C$8="All")>0)*(('[1]Calc - Loan Summary'!$E$5:$E$24=$C$9)+($C$9="All")>0)*('[1]Calc - Loan Summary'!$G$5:$G$24=$B33)*('[1]Calc - Loan Summary'!$C$5:$C$24="Business Loan")*'[1]Calc - Loan Summary'!$H$5:$H$24) -> 0 | D33: =SUMPRODUCT(('[1]Calc - Loan Summary'!$J$5:$J$24=1)*(('[1]Calc - Loan Summary'!$C$5:$C$24=$C$7)+($C$7="All")>0)*(('[1]Calc - Loan Summary'!$D$5:$D$24=$C$8)+($C$8="All")>0)*(('[1]Calc - Loan Summary'!$E$5:$E$24=$C$9)+($C$9="All")>0)*('[1]Calc - Loan Summary'!$G$5:$G$24=$B33)*('[1]Calc - Loan Summary'!$C$5:$C$24="Personal Loan")*'[1]Calc - Loan Summary'!$H$5:$H$24) -> 0 | E33: =SUMPRODUCT(('[1]Calc - Loan Summary'!$J$5:$J$24=1)*(('[1]Calc - Loan Summary'!$C$5:$C$24=$C$7)+($C$7="All")>0)*(('[1]Calc - Loan Summary'!$D$5:$D$24=$C$8)+($C$8="All")>0)*(('[1]Calc - Loan Summary'!$E$5:$E$24=$C$9)+($C$9="All")>0)*('[1]Calc - Loan Summary'!$G$5:$G$24=$B33)*('[1]Calc - Loan Summary'!$C$5:$C$24="Salary Advance")*'[1]Calc - Loan Summary'!$H$5:$H$24) -> 130000 | F33: =SUM(C33:E33) -> 130000
B34: Total | C34: =SUM(C30:C33) -> 640000 | D34: =SUM(D30:D33) -> 935000 | E34: =SUM(E30:E33) -> 630000 | F34: =SUM(F30:F33) -> 2205000
B35: Values = principal disbursed (₦), filtered by Reporting Date, Product, Channel and Customer Type above.
B37: Actions Supported by These Results
B38: 1. Trigger early collections outreach at first delinquency (1–7 DPD), not just at 90+.
B39: Every currently delinquent loan in the book has already crossed 90+ DPD — there is currently no population sitting in the 1–60 day buckets. That means the book's early-warning stage is effectively empty: loans appear to jump straight from Current to severely delinquent, most likely because collections only start once accounts are already very late. Add a structured outreach step (SMS/call) as soon as an instalment is 1–7 days overdue.
B40: Owner: | C40: Collections Team Lead
B41: Monitoring metric: | C41: Loan count and ₦ value in the 1–7, 8–30 and 31–60 DPD buckets (Dashboard delinquency table) — review weekly. If this population stays near zero after the process is live, it confirms loans are genuinely cured quickly; if it starts filling and 90+ volume falls, it shows the new step is catching cases before they become severely delinquent.
B43: 2. Reconcile the 3 loans with missing payment-amount data before reporting collection rate externally.
B44: L015, L016 and L018 (₦435,600 of contractual exposure, ~15% of the book) have a payment_date recorded but no payment_amount in the source system, so this dashboard conservatively treats them as ₦0 collected. If payments were in fact received, both Amount Collected and Collection Rate are currently understated, and these three loans are overstated in the 90+ bucket.
B45: Owner: | C45: Data/Systems Analyst (Loan Operations), with sign-off from Finance before external reporting
B46: Monitoring metric: | C46: Count of Installment rows with a payment_date but blank payment_amount (Reconciliation tab, issue log row 4) — target zero before each external report; re-check portfolio Collection Rate once fixed.
